Workbook

Sheet Raw Data
A1: Liberation Day Market Analysis (Mar 25 – Apr 15, 2025)
B2: Yahoo Finance (Adj. Close) | E2: FRED — Treasury Yields (%) | G2: FRED — Credit Spreads (%)
A3: Date | B3: S&P 500 (^GSPC) | C3: Nasdaq (^IXIC) | D3: VIX (^VIX) | E3: 10-Year Yield | F3: 2-Year Yield | G3: HY OAS (BAMLH0A0HYM2) | H3: IG OAS (BAMLC0A0CM)
A4: 25-Mar-25 | B4: 5776.65 | C4: 18271.86 | D4: 17.15 | E4: 0.0431 | F4: 0.0396 | G4: 0.0309 | H4: 0.009
A5: 26-Mar-25 | B5: 5712.2 | C5: 17899.02 | D5: 18.33 | E5: 0.0435 | F5: 0.0398 | G5: 0.0319 | H5: 0.0091
A6: 27-Mar-25 | B6: 5693.31 | C6: 17804.03 | D6: 18.69 | E6: 0.0438 | F6: 0.0397 | G6: 0.0327 | H6: 0.0091
A7: 28-Mar-25 | B7: 5580.94 | C7: 17322.99 | D7: 21.65 | E7: 0.0427 | F7: 0.0389 | G7: 0.0347 | H7: 0.0094
A8: 31-Mar-25 | B8: 5611.85 | C8: 17299.29 | D8: 22.28 | E8: 0.0423 | F8: 0.0389 | G8: 0.0355 | H8: 0.0097
A9: 01-Apr-25 | B9: 5633.07 | C9: 17449.89 | D9: 21.77 | E9: 0.0417 | F9: 0.0387 | G9: 0.035 | H9: 0.0098 | I9: ◄ Apr 2 – Liberation Day
A10: 02-Apr-25 | B10: 5670.97 | C10: 17601.05 | D10: 21.51 | E10: 0.042 | F10: 0.0391 | G10: 0.0342 | H10: 0.0096
A11: 03-Apr-25 | B11: 5396.52 | C11: 16550.61 | D11: 30.02 | E11: 0.0406 | F11: 0.0371 | G11: 0.0401 | H11: 0.0106
A12: 04-Apr-25 | B12: 5074.08 | C12: 15587.79 | D12: 45.31 | E12: 0.0401 | F12: 0.0368 | G12: 0.0445 | H12: 0.0114
A13: 07-Apr-25 | B13: 5062.25 | C13: 15603.26 | D13: 46.98 | E13: 0.0415 | F13: 0.0373 | G13: 0.0461 | H13: 0.012
A14: 08-Apr-25 | B14: 4982.77 | C14: 15267.91 | D14: 52.33 | E14: 0.0426 | F14: 0.0371 | G14: 0.0457 | H14: 0.0118 | I14: ◄ Apr 9 – 90-day pause
A15: 09-Apr-25 | B15: 5456.9 | C15: 17124.97 | D15: 33.62 | E15: 0.0434 | F15: 0.0391 | G15: 0.0437 | H15: 0.0121
A16: 10-Apr-25 | B16: 5268.05 | C16: 16387.31 | D16: 40.72 | E16: 0.044 | F16: 0.0384 | G16: 0.0442 | H16: 0.0118
A17: 11-Apr-25 | B17: 5363.36 | C17: 16724.46 | D17: 37.56 | E17: 0.0448 | F17: 0.0396 | G17: 0.0426 | H17: 0.0118
A18: 14-Apr-25 | B18: 5405.97 | C18: 16831.48 | D18: 30.89 | E18: 0.0438 | F18: 0.0384 | G18: 0.0414 | H18: 0.0115
A19: 15-Apr-25 | B19: 5396.63 | C19: 16823.17 | D19: 30.12 | E19: 0.0435 | F19: 0.0384 | G19: 0.0409 | H19: 0.0114

Sheet Calculations
A1: Calculations (Daily Returns, Cumulative Returns, Yield & Spread Changes)
A2: A. Daily Returns & Index/Spread Levels
A3: Date | B3: S&P 500 Adj. Close | C3: S&P 500 Daily Return | D3: Nasdaq Adj. Close | E3: Nasdaq Daily Return | F3: VIX Close | G3: 10Y Yield (%) | H3: 2Y Yield (%) | I3: HY OAS (bps) | J3: IG OAS (bps)
A4: ='Raw Data'!A4 -> 25-Mar-25 | B4: ='Raw Data'!B4 -> 5776.65 | C4: N/A | D4: ='Raw Data'!C4 -> 18271.86 | E4: N/A | F4: ='Raw Data'!D4 -> 17.15 | G4: ='Raw Data'!E4*100 -> 4.31 | H4: ='Raw Data'!F4*100 -> 3.96 | I4: ='Raw Data'!G4*10000 -> 309 | J4: ='Raw Data'!H4*10000 -> 90
A5: ='Raw Data'!A5 -> 26-Mar-25 | B5: ='Raw Data'!B5 -> 5712.2 | C5: =('Raw Data'!B5-'Raw Data'!B4)/'Raw Data'!B4 -> -0.011156985 | D5: ='Raw Data'!C5 -> 17899.02 | E5: =('Raw Data'!C5-'Raw Data'!C4)/'Raw Data'!C4 -> -0.020405148 | F5: ='Raw Data'!D5 -> 18.33 | G5: ='Raw Data'!E5*100 -> 4.35 | H5: ='Raw Data'!F5*100 -> 3.98 | I5: ='Raw Data'!G5*10000 -> 319 | J5: ='Raw Data'!H5*10000 -> 91
A6: ='Raw Data'!A6 -> 27-Mar-25 | B6: ='Raw Data'!B6 -> 5693.31 | C6: =('Raw Data'!B6-'Raw Data'!B5)/'Raw Data'!B5 -> -0.003306957 | D6: ='Raw Data'!C6 -> 17804.03 | E6: =('Raw Data'!C6-'Raw Data'!C5)/'Raw Data'!C5 -> -0.0053069945 | F6: ='Raw Data'!D6 -> 18.69 | G6: ='Raw Data'!E6*100 -> 4.38 | H6: ='Raw Data'!F6*100 -> 3.97 | I6: ='Raw Data'!G6*10000 -> 327 | J6: ='Raw Data'!H6*10000 -> 91
A7: ='Raw Data'!A7 -> 28-Mar-25 | B7: ='Raw Data'!B7 -> 5580.94 | C7: =('Raw Data'!B7-'Raw Data'!B6)/'Raw Data'!B6 -> -0.0197372 | D7: ='Raw Data'!C7 -> 17322.99 | E7: =('Raw Data'!C7-'Raw Data'!C6)/'Raw Data'!C6 -> -0.027018602 | F7: ='Raw Data'!D7 -> 21.65 | G7: ='Raw Data'!E7*100 -> 4.27 | H7: ='Raw Data'!F7*100 -> 3.89 | I7: ='Raw Data'!G7*10000 -> 347 | J7: ='Raw Data'!H7*10000 -> 94
A8: ='Raw Data'!A8 -> 31-Mar-25 | B8: ='Raw Data'!B8 -> 5611.85 | C8: =('Raw Data'!B8-'Raw Data'!B7)/'Raw Data'!B7 -> 0.0055384935 | D8: ='Raw Data'!C8 -> 17299.29 | E8: =('Raw Data'!C8-'Raw Data'!C7)/'Raw Data'!C7 -> -0.0013681241 | F8: ='Raw Data'!D8 -> 22.28 | G8: ='Raw Data'!E8*100 -> 4.23 | H8: ='Raw Data'!F8*100 -> 3.89 | I8: ='Raw Data'!G8*10000 -> 355 | J8: ='Raw Data'!H8*10000 -> 97 | L8: 1% = 100 BSP, 3.09% should be reported as 309 bps.
A9: ='Raw Data'!A9 -> 01-Apr-25 | B9: ='Raw Data'!B9 -> 5633.07 | C9: =('Raw Data'!B9-'Raw Data'!B8)/'Raw Data'!B8 -> 0.0037812842 | D9: ='Raw Data'!C9 -> 17449.89 | E9: =('Raw Data'!C9-'Raw Data'!C8)/'Raw Data'!C8 -> 0.0087055596 | F9: ='Raw Data'!D9 -> 21.77 | G9: ='Raw Data'!E9*100 -> 4.17 | H9: ='Raw Data'!F9*100 -> 3.87 | I9: ='Raw Data'!G9*10000 -> 350 | J9: ='Raw Data'!H9*10000 -> 98
A10: ='Raw Data'!A10 -> 02-Apr-25 | B10: ='Raw Data'!B10 -> 5670.97 | C10: =('Raw Data'!B10-'Raw Data'!B9)/'Raw Data'!B9 -> 0.0067281252 | D10: ='Raw Data'!C10 -> 17601.05 | E10: =('Raw Data'!C10-'Raw Data'!C9)/'Raw Data'!C9 -> 0.0086625188 | F10: ='Raw Data'!D10 -> 21.51 | G10: ='Raw Data'!E10*100 -> 4.2 | H10: ='Raw Data'!F10*100 -> 3.91 | I10: ='Raw Data'!G10*10000 -> 342 | J10: ='Raw Data'!H10*10000 -> 96
A11: ='Raw Data'!A11 -> 03-Apr-25 | B11: ='Raw Data'!B11 -> 5396.52 | C11: =('Raw Data'!B11-'Raw Data'!B10)/'Raw Data'!B10 -> -0.048395601 | D11: ='Raw Data'!C11 -> 16550.61 | E11: =('Raw Data'!C11-'Raw Data'!C10)/'Raw Data'!C10 -> -0.05968053 | F11: ='Raw Data'!D11 -> 30.02 | G11: ='Raw Data'!E11*100 -> 4.06 | H11: ='Raw Data'!F11*100 -> 3.71 | I11: ='Raw Data'!G11*10000 -> 401 | J11: ='Raw Data'!H11*10000 -> 106
A12: ='Raw Data'!A12 -> 04-Apr-25 | B12: ='Raw Data'!B12 -> 5074.08 | C12: =('Raw Data'!B12-'Raw Data'!B11)/'Raw Data'!B11 -> -0.059749616 | D12: ='Raw Data'!C12 -> 15587.79 | E12: =('Raw Data'!C12-'Raw Data'!C11)/'Raw Data'!C11 -> -0.058174291 | F12: ='Raw Data'!D12 -> 45.31 | G12: ='Raw Data'!E12*100 -> 4.01 | H12: ='Raw Data'!F12*100 -> 3.68 | I12: ='Raw Data'!G12*10000 -> 445 | J12: ='Raw Data'!H12*10000 -> 114
A13: ='Raw Data'!A13 -> 07-Apr-25 | B13: ='Raw Data'!B13 -> 5062.25 | C13: =('Raw Data'!B13-'Raw Data'!B12)/'Raw Data'!B12 -> -0.0023314571 | D13: ='Raw Data'!C13 -> 15603.26 | E13: =('Raw Data'!C13-'Raw Data'!C12)/'Raw Data'!C12 -> 0.00099244344 | F13: ='Raw Data'!D13 -> 46.98 | G13: ='Raw Data'!E13*100 -> 4.15 | H13: ='Raw Data'!F13*100 -> 3.73 | I13: ='Raw Data'!G13*10000 -> 461 | J13: ='Raw Data'!H13*10000 -> 120
A14: ='Raw Data'!A14 -> 08-Apr-25 | B14: ='Raw Data'!B14 -> 4982.77 | C14: =('Raw Data'!B14-'Raw Data'!B13)/'Raw Data'!B13 -> -0.015700528 | D14: ='Raw Data'!C14 -> 15267.91 | E14: =('Raw Data'!C14-'Raw Data'!C13)/'Raw Data'!C13 -> -0.021492304 | F14: ='Raw Data'!D14 -> 52.33 | G14: ='Raw Data'!E14*100 -> 4.26 | H14: ='Raw Data'!F14*100 -> 3.71 | I14: ='Raw Data'!G14*10000 -> 457 | J14: ='Raw Data'!H14*10000 -> 118
A15: ='Raw Data'!A15 -> 09-Apr-25 | B15: ='Raw Data'!B15 -> 5456.9 | C15: =('Raw Data'!B15-'Raw Data'!B14)/'Raw Data'!B14 -> 0.0951539 | D15: ='Raw Data'!C15 -> 17124.97 | E15: =('Raw Data'!C15-'Raw Data'!C14)/'Raw Data'!C14 -> 0.12163158 | F15: ='Raw Data'!D15 -> 33.62 | G15: ='Raw Data'!E15*100 -> 4.34 | H15: ='Raw Data'!F15*100 -> 3.91 | I15: ='Raw Data'!G15*10000 -> 437 | J15: ='Raw Data'!H15*10000 -> 121
A16: ='Raw Data'!A16 -> 10-Apr-25 | B16: ='Raw Data'!B16 -> 5268.05 | C16: =('Raw Data'!B16-'Raw Data'!B15)/'Raw Data'!B15 -> -0.034607561 | D16: ='Raw Data'!C16 -> 16387.31 | E16: =('Raw Data'!C16-'Raw Data'!C15)/'Raw Data'!C15 -> -0.043075112 | F16: ='Raw Data'!D16 -> 40.72 | G16: ='Raw Data'!E16*100 -> 4.4 | H16: ='Raw Data'!F16*100 -> 3.84 | I16: ='Raw Data'!G16*10000 -> 442 | J16: ='Raw Data'!H16*10000 -> 118
A17: ='Raw Data'!A17 -> 11-Apr-25 | B17: ='Raw Data'!B17 -> 5363.36 | C17: =('Raw Data'!B17-'Raw Data'!B16)/'Raw Data'!B16 -> 0.018092083 | D17: ='Raw Data'!C17 -> 16724.46 | E17: =('Raw Data'!C17-'Raw Data'!C16)/'Raw Data'!C16 -> 0.020573846 | F17: ='Raw Data'!D17 -> 37.56 | G17: ='Raw Data'!E17*100 -> 4.48 | H17: ='Raw Data'!F17*100 -> 3.96 | I17: ='Raw Data'!G17*10000 -> 426 | J17: ='Raw Data'!H17*10000 -> 118
A18: ='Raw Data'!A18 -> 14-Apr-25 | B18: ='Raw Data'!B18 -> 5405.97 | C18: =('Raw Data'!B18-'Raw Data'!B17)/'Raw Data'!B17 -> 0.0079446466 | D18: ='Raw Data'!C18 -> 16831.48 | E18: =('Raw Data'!C18-'Raw Data'!C17)/'Raw Data'!C17 -> 0.0063990108 | F18: ='Raw Data'!D18 -> 30.89 | G18: ='Raw Data'!E18*100 -> 4.38 | H18: ='Raw Data'!F18*100 -> 3.84 | I18: ='Raw Data'!G18*10000 -> 414 | J18: ='Raw Data'!H18*10000 -> 115
A19: ='Raw Data'!A19 -> 15-Apr-25 | B19: ='Raw Data'!B19 -> 5396.63 | C19: =('Raw Data'!B19-'Raw Data'!B18)/'Raw Data'!B18 -> -0.0017277195 | D19: ='Raw Data'!C19 -> 16823.17 | E19: =('Raw Data'!C19-'Raw Data'!C18)/'Raw Data'!C18 -> -0.00049371772 | F19: ='Raw Data'!D19 -> 30.12 | G19: ='Raw Data'!E19*100 -> 4.35 | H19: ='Raw Data'!F19*100 -> 3.84 | I19: ='Raw Data'!G19*10000 -> 409 | J19: ='Raw Data'!H19*10000 -> 114
A22: B. Cumulative (Holding-Period) Returns
A23: Window | B23: Start Date | C23: End Date | D23: S&P 500 Cum. Return | E23: Nasdaq Cum. Return
A24: Apr 2 → Apr 4 | B24: Apr 2, 2025 | C24: Apr 4, 2025 | D24: =('Raw Data'!B12-'Raw Data'!B10)/'Raw Data'!B10 -> -0.1052536 | E24: =('Raw Data'!C12-'Raw Data'!C10)/'Raw Data'!C10 -> -0.11438295
A25: Apr 2 → Apr 9 | B25: Apr 2, 2025 | C25: Apr 9, 2025 | D25: =('Raw Data'!B15-'Raw Data'!B10)/'Raw Data'!B10 -> -0.037748392 | E25: =('Raw Data'!C15-'Raw Data'!C10)/'Raw Data'!C10 -> -0.027048386
A26: Apr 9 → Apr 11 | B26: Apr 9, 2025 | C26: Apr 11, 2025 | D26: =('Raw Data'!B17-'Raw Data'!B15)/'Raw Data'!B15 -> -0.017141601 | E26: =('Raw Data'!C17-'Raw Data'!C15)/'Raw Data'!C15 -> -0.023387486
A29: C. Yield & Spread Changes vs. Apr 2 Baseline
A30: Metric | B30: Apr 2 Level | C30: Apr 4 Level | D30: Change (Apr 2→4) | E30: Apr 9 Level | F30: Change (Apr 2→9) | G30: Apr 11 Level | H30: Change (Apr 2→11)
A31: 10-Year Treasury Yield (%) | B31: ='Raw Data'!E10*100 -> 4.2 | C31: ='Raw Data'!E12*100 -> 4.01 | D31: =('Raw Data'!E12-'Raw Data'!E10)*100 -> -0.19 | E31: ='Raw Data'!E15*100 -> 4.34 | F31: =('Raw Data'!E15-'Raw Data'!E10)*100 -> 0.14 | G31: ='Raw Data'!E17*100 -> 4.48 | H31: =('Raw Data'!E17-'Raw Data'!E10)*100 -> 0.28
A32: 2-Year Treasury Yield (%) | B32: ='Raw Data'!F10*100 -> 3.91 | C32: ='Raw Data'!F12*100 -> 3.68 | D32: =('Raw Data'!F12-'Raw Data'!F10)*100 -> -0.23 | E32: ='Raw Data'!F15*100 -> 3.91 | F32: =('Raw Data'!F15-'Raw Data'!F10)*100 -> 0 | G32: ='Raw Data'!F17*100 -> 3.96 | H32: =('Raw Data'!F17-'Raw Data'!F10)*100 -> 0.05
A33: High Yield Option-Adjusted Spread (bps) | B33: ='Raw Data'!G10*10000 -> 342 | C33: ='Raw Data'!G12*10000 -> 445 | D33: =('Raw Data'!G12-'Raw Data'!G10)*10000 -> 103 | E33: ='Raw Data'!G15*10000 -> 437 | F33: =('Raw Data'!G15-'Raw Data'!G10)*10000 -> 95 | G33: ='Raw Data'!G17*10000 -> 426 | H33: =('Raw Data'!G17-'Raw Data'!G10)*10000 -> 84
A34: Investment Grade Option-Adjusted Spread (bps) | B34: ='Raw Data'!H10*10000 -> 96 | C34: ='Raw Data'!H12*10000 -> 114 | D34: =('Raw Data'!H12-'Raw Data'!H10)*10000 -> 18 | E34: ='Raw Data'!H15*10000 -> 121 | F34: =('Raw Data'!H15-'Raw Data'!H10)*10000 -> 25 | G34: ='Raw Data'!H17*10000 -> 118 | H34: =('Raw Data'!H17-'Raw Data'!H10)*10000 -> 22

Sheet Chart Data
A1: Chart Data
A2: Chart 1 – S&P 500 & Nasdaq Levels
A3: Date | B3: S&P 500 (Adj. Close) | C3: Nasdaq (Adj. Close)
A4: =Calculations!A4 -> 25-Mar-25 | B4: =Calculations!B4 -> 5776.65 | C4: =Calculations!D4 -> 18271.86
A5: =Calculations!A5 -> 26-Mar-25 | B5: =Calculations!B5 -> 5712.2 | C5: =Calculations!D5 -> 17899.02
A6: =Calculations!A6 -> 27-Mar-25 | B6: =Calculations!B6 -> 5693.31 | C6: =Calculations!D6 -> 17804.03
A7: =Calculations!A7 -> 28-Mar-25 | B7: =Calculations!B7 -> 5580.94 | C7: =Calculations!D7 -> 17322.99
A8: =Calculations!A8 -> 31-Mar-25 | B8: =Calculations!B8 -> 5611.85 | C8: =Calculations!D8 -> 17299.29
A9: =Calculations!A9 -> 01-Apr-25 | B9: =Calculations!B9 -> 5633.07 | C9: =Calculations!D9 -> 17449.89
A10: =Calculations!A10 -> 02-Apr-25 | B10: =Calculations!B10 -> 5670.97 | C10: =Calculations!D10 -> 17601.05
A11: =Calculations!A11 -> 03-Apr-25 | B11: =Calculations!B11 -> 5396.52 | C11: =Calculations!D11 -> 16550.61
A12: =Calculations!A12 -> 04-Apr-25 | B12: =Calculations!B12 -> 5074.08 | C12: =Calculations!D12 -> 15587.79
A13: =Calculations!A13 -> 07-Apr-25 | B13: =Calculations!B13 -> 5062.25 | C13: =Calculations!D13 -> 15603.26
A14: =Calculations!A14 -> 08-Apr-25 | B14: =Calculations!B14 -> 4982.77 | C14: =Calculations!D14 -> 15267.91
A15: =Calculations!A15 -> 09-Apr-25 | B15: =Calculations!B15 -> 5456.9 | C15: =Calculations!D15 -> 17124.97
... A19: =Calculations!A19 -> 15-Apr-25 | B19: =Calculations!B19 -> 5396.63 | C19: =Calculations!D19 -> 16823.17
A20: Chart 2 – VIX Level
A21: Date | B21: VIX Close
A22: =Calculations!A4 -> 25-Mar-25 | B22: =Calculations!F4 -> 17.15
A23: =Calculations!A5 -> 26-Mar-25 | B23: =Calculations!F5 -> 18.33
A24: =Calculations!A6 -> 27-Mar-25 | B24: =Calculations!F6 -> 18.69
A25: =Calculations!A7 -> 28-Mar-25 | B25: =Calculations!F7 -> 21.65
A26: =Calculations!A8 -> 31-Mar-25 | B26: =Calculations!F8 -> 22.28
A27: =Calculations!A9 -> 01-Apr-25 | B27: =Calculations!F9 -> 21.77
A28: =Calculations!A10 -> 02-Apr-25 | B28: =Calculations!F10 -> 21.51
A29: =Calculations!A11 -> 03-Apr-25 | B29: =Calculations!F11 -> 30.02
A30: =Calculations!A12 -> 04-Apr-25 | B30: =Calculations!F12 -> 45.31
A31: =Calculations!A13 -> 07-Apr-25 | B31: =Calculations!F13 -> 46.98
A32: =Calculations!A14 -> 08-Apr-25 | B32: =Calculations!F14 -> 52.33
A33: =Calculations!A15 -> 09-Apr-25 | B33: =Calculations!F15 -> 33.62
... A37: =Calculations!A19 -> 15-Apr-25 | B37: =Calculations!F19 -> 30.12
A38: Chart 3 – Daily Returns
A39: Date | B39: S&P 500 Daily Return | C39: Nasdaq Daily Return
A40: =Calculations!A4 -> 25-Mar-25 | B40: =Calculations!C4 -> N/A | C40: =Calculations!E4 -> N/A
A41: =Calculations!A5 -> 26-Mar-25 | B41: =Calculations!C5 -> -0.011156985 | C41: =Calculations!E5 -> -0.020405148
A42: =Calculations!A6 -> 27-Mar-25 | B42: =Calculations!C6 -> -0.003306957 | C42: =Calculations!E6 -> -0.0053069945
A43: =Calculations!A7 -> 28-Mar-25 | B43: =Calculations!C7 -> -0.0197372 | C43: =Calculations!E7 -> -0.027018602
A44: =Calculations!A8 -> 31-Mar-25 | B44: =Calculations!C8 -> 0.0055384935 | C44: =Calculations!E8 -> -0.0013681241
A45: =Calculations!A9 -> 01-Apr-25 | B45: =Calculations!C9 -> 0.0037812842 | C45: =Calculations!E9 -> 0.0087055596
A46: =Calculations!A10 -> 02-Apr-25 | B46: =Calculations!C10 -> 0.0067281252 | C46: =Calculations!E10 -> 0.0086625188
...

Sheet Charts
B3: Chart 1: S&P 500 & Nasdaq Levels | L3: Chart 2: VIX Volatility Index
B33: Chart 3: Daily Returns (%) | L33: Chart 4: Treasury Yields (%)
B63: Chart 5 — Credit Spreads (bps) | L63: Chart 6 — Cumulative Returns from Apr 2
B93: Chart 7 — HY vs. IG Credit Spreads (bps)
